<?xml version="1.0" ?>
<robot name="sixdofarm">

  <material name="red">
    <color rgba="1.0 0.0 0.0 1.0"/>
  </material>

  <material name="green">
    <color rgba="0.0 1.0 0.0 1.0"/>
  </material>

  <material name="blue">
    <color rgba="0.0 0.0 1.0 1.0"/>
  </material>




  <!-- world -->
  <link name="world"/>


  
  <joint name="world_2_base_link" type="fixed">
    <parent link="world"/>
    <child link="base_link"/>
    <origin rpy="0 0 0" xyz="0 0 0"/>
    
  </joint>
  




  <!-- base_link -->
  <link name="base_link">
    <collision>
      <origin rpy="0 0 0" xyz="0 0 0"/>
      <geometry>
        <box size="0.5 0.5 0.001"/>
      </geometry>
    </collision>

    <visual>
      <origin rpy="0 0 0" xyz="0 0 0"/>
      <geometry>
        <box size="0.5 0.5 0.001"/>
      </geometry>
      <material name="blue"/>
    </visual>

    <inertial>
      <origin rpy="0 0 0" xyz="0 0 0"/>
      <mass value="0"/>
      <inertia ixx="0" ixy="0" ixz="0" iyy="0" iyz="0" izz="0"/>
    </inertial>
  </link>


  
  <joint name="base_link_2_Link1" type="fixed">
    <parent link="base_link"/>
    <child link="Link1"/>
    <origin rpy="0 0 0" xyz="0 0 0.0"/>
    
  </joint>
  




  <!-- Link1 -->
  <link name="Link1">
    <collision>
      <origin rpy="0 0 0" xyz="0 0 0.06578"/>
      <geometry>
        <box size="0 0 0.13156"/>
      </geometry>
    </collision>

    <visual>
      <origin rpy="0 0 0" xyz="0 0 0.06578"/>
      <geometry>
        <box size="0 0 0.13156"/>
      </geometry>
      <material name="red"/>
    </visual>

    <inertial>
      <origin rpy="0 0 0" xyz="0 0 0.06578"/>
      <mass value="1"/>
      <inertia ixx="1" ixy="0" ixz="0" iyy="1" iyz="0" izz="1"/>
    </inertial>
  </link>


  
  <joint name="Link1_2_Link2" type="revolute">
    <parent link="Link1"/>
    <child link="Link2"/>
    <origin rpy="0 0 0" xyz="0 0 0.13156"/>
    
    <axis xyz="0 0 1"/>
    <limit effort="30" lower="-2.616" upper="2.617" velocity="1.571"/>
    
  </joint>
  




  <!-- Link2 -->
  <link name="Link2">
    <collision>
      <origin rpy="0 0 0" xyz="0 0 0"/>
      <geometry>
        <box size="0.01 0.01 0.01"/>
      </geometry>
    </collision>

    <visual>
      <origin rpy="0 0 0" xyz="0 0 0"/>
      <geometry>
        <box size="0.01 0.01 0.01"/>
      </geometry>
      <material name="green"/>
    </visual>

    <inertial>
      <origin rpy="0 0 0" xyz="0 0 0"/>
      <mass value="1"/>
      <inertia ixx="1" ixy="0" ixz="0" iyy="1" iyz="0" izz="1"/>
    </inertial>
  </link>


  
  <joint name="Link2_2_Link3" type="revolute">
    <parent link="Link2"/>
    <child link="Link3"/>
    <origin rpy="0 0 0" xyz="0 0 0"/>
    
    <axis xyz="0 1 0"/>
    <limit effort="30" lower="-2.616" upper="2.617" velocity="1.571"/>
    
  </joint>
  




  <!-- Link3 -->
  <link name="Link3">
    <collision>
      <origin rpy="0 0 0" xyz="0 0 0.0552"/>
      <geometry>
        <box size="0.04 0.04 0.1104"/>
      </geometry>
    </collision>

    <visual>
      <origin rpy="0 0 0" xyz="0 0 0.0552"/>
      <geometry>
        <box size="0.04 0.04 0.1104"/>
      </geometry>
      <material name="blue"/>
    </visual>

    <inertial>
      <origin rpy="0 0 0" xyz="0 0 0.0552"/>
      <mass value="1"/>
      <inertia ixx="1" ixy="0" ixz="0" iyy="1" iyz="0" izz="1"/>
    </inertial>
  </link>


  
  <joint name="Link3_2_Link4" type="revolute">
    <parent link="Link3"/>
    <child link="Link4"/>
    <origin rpy="0 0 0" xyz="0 0 0.1104"/>
    
    <axis xyz="0 1 0"/>
    <limit effort="30" lower="-2.616" upper="2.617" velocity="1.571"/>
    
  </joint>
  




  <!-- Link4 -->
  <link name="Link4">
    <collision>
      <origin rpy="0 0 0" xyz="0 0 0.048"/>
      <geometry>
        <box size="0.04 0.04 0.096"/>
      </geometry>
    </collision>

    <visual>
      <origin rpy="0 0 0" xyz="0 0 0.048"/>
      <geometry>
        <box size="0.04 0.04 0.096"/>
      </geometry>
      <material name="red"/>
    </visual>

    <inertial>
      <origin rpy="0 0 0" xyz="0 0 0.048"/>
      <mass value="1"/>
      <inertia ixx="1" ixy="0" ixz="0" iyy="1" iyz="0" izz="1"/>
    </inertial>
  </link>


  
  <joint name="Link4_2_Link5" type="revolute">
    <parent link="Link4"/>
    <child link="Link5"/>
    <origin rpy="0 0 0" xyz="0 0 0.096"/>
    
    <axis xyz="0 0 1"/>
    <limit effort="30" lower="-2.616" upper="2.617" velocity="1.571"/>
    
  </joint>
  




  <!-- Link5 -->
  <link name="Link5">
    <collision>
      <origin rpy="0 0 0" xyz="0 0.03231 0.03659"/>
      <geometry>
        <box size="0 0.06462 0.07318"/>
      </geometry>
    </collision>

    <visual>
      <origin rpy="0 0 0" xyz="0 0.03231 0.03659"/>
      <geometry>
        <box size="0 0.06462 0.07318"/>
      </geometry>
      <material name="green"/>
    </visual>

    <inertial>
      <origin rpy="0 0 0" xyz="0 0.03231 0.03659"/>
      <mass value="1"/>
      <inertia ixx="1" ixy="0" ixz="0" iyy="1" iyz="0" izz="1"/>
    </inertial>
  </link>


  
  <joint name="Link5_2_Link6" type="revolute">
    <parent link="Link5"/>
    <child link="Link6"/>
    <origin rpy="0 0 0" xyz="0 0.06462 0.07318"/>
    
    <axis xyz="0 1 0"/>
    <limit effort="30" lower="-2.616" upper="2.617" velocity="1.571"/>
    
  </joint>
  




  <!-- Link6 -->
  <link name="Link6">
    <collision>
      <origin rpy="0 0 0" xyz="0 0.0243 0"/>
      <geometry>
        <box size="0.04 0.0486 0.04"/>
      </geometry>
    </collision>

    <visual>
      <origin rpy="0 0 0" xyz="0 0.0243 0"/>
      <geometry>
        <box size="0.04 0.0486 0.04"/>
      </geometry>
      <material name="blue"/>
    </visual>

    <inertial>
      <origin rpy="0 0 0" xyz="0 0.0243 0"/>
      <mass value="1"/>
      <inertia ixx="1" ixy="0" ixz="0" iyy="1" iyz="0" izz="1"/>
    </inertial>
  </link>


  
  <joint name="Link6_2_Link7" type="revolute">
    <parent link="Link6"/>
    <child link="Link7"/>
    <origin rpy="0 0 0" xyz="0 0.0486 0"/>
    
    <axis xyz="0 0 1"/>
    <limit effort="30" lower="-2.616" upper="2.617" velocity="1.571"/>
    
  </joint>
  




  <!-- Link7 -->
  <link name="Link7">
    <collision>
      <origin rpy="0 0 0" xyz="0 0 0.02"/>
      <geometry>
        <box size="0.04 0.04 0.04"/>
      </geometry>
    </collision>

    <visual>
      <origin rpy="0 0 0" xyz="0 0 0.02"/>
      <geometry>
        <box size="0.04 0.04 0.04"/>
      </geometry>
      <material name="red"/>
    </visual>

    <inertial>
      <origin rpy="0 0 0" xyz="0 0 0.02"/>
      <mass value="1"/>
      <inertia ixx="1" ixy="0" ixz="0" iyy="1" iyz="0" izz="1"/>
    </inertial>
  </link>


  



</robot>